Workbook

Sheet Dashboard
A1: FlexBay - Integrated Financial Model - Dashboard
A2: Group 3 | MGMT 637 | 10-year hold, monthly model
A4: CAPITALIZATION
A5: Total project cost (all-in) | B5: ='Acq & Financing'!D10 -> 150271875
A6: Senior debt | B6: ='Acq & Financing'!E10 -> 97676719
A7: Total equity | B7: ='Acq & Financing'!F10 -> 52595156
A8: Portfolio size at year 10 (SF) | B8: =Assumptions!B10 -> 1250000
A10: RETURNS (LEVERED, PRE-TAX)
A11: Portfolio IRR | B11: ='Operating Model'!B56 -> 0.12740644
A12: Equity multiple | B12: ='Operating Model'!B59 -> 2.4494764
A13: Stabilized NOI (exit basis) | B13: ='Operating Model'!B51 -> 13904694
A14: Gross exit value | B14: ='Operating Model'!B53 -> 2.1391837e+08
A15: Net exit proceeds | B15: ='Operating Model'!B55 -> 1.1089369e+08
A17: YEAR-3 SUSTAINABILITY
A18: Year-3 net cash flow (levered) | B18: ='Annual Summary'!E8 -> -1352047.1
A19: Year-3 occupancy (year-end) | B19: ='Annual Summary'!E11 -> 0.6
A20: Verdict | B20: =IF('Annual Summary'!E8>=0,"Self-sustaining by Year 3","NOT self-sustaining in Year 3 (lease-up + growth drag)") -> NOT self-sustaining in Year 3 (lease-up + growth drag)
A23: MODELING NOTES
A24: Debt is interest-only with a balloon repaid at the year-10 sale (standard value-add hold).
A25: Profit recycling (25% of cash into next deal) is internal financing, it nets out of consolidated cash flow and IRR.
A26: Exit valued on fully-stabilized portfolio NOI at the exit cap rate.
A27: AI assisted in developing assumption benchmarks, each AI-assisted figure is documented in a comment on the Assumptions tab.
A28: Important to note that AI assisted values are derived from JLL, CoStar, and LoopNet market and indsutry data.

Sheet Assumptions
A1: FlexBay - Integrated Financial Model: Assumptions
A2: Blue = input (change for scenarios). Black = formula. AI-assisted cells carry a comment explaining derivation.
A3: Building | B3: Size (SF) | C3: Acq. Month | D3: Acq. Year | E3: Debt Rate
A4: Flagship (Bldg 1) | B4: 175000 | C4: 1 | D4: =INT((C4-1)/12)+1 -> 1 | E4: 0.0675
A5: Building 2 | B5: 175000 | C5: 25 | D5: =INT((C5-1)/12)+1 -> 3 | E5: 0.0675
A6: Building 3 | B6: 150000 | C6: 37 | D6: =INT((C6-1)/12)+1 -> 4 | E6: 0.06
A7: Building 4 | B7: 250000 | C7: 49 | D7: =INT((C7-1)/12)+1 -> 5 | E7: 0.06
A8: Building 5 | B8: 250000 | C8: 61 | D8: =INT((C8-1)/12)+1 -> 6 | E8: 0.0575
A9: Building 6 | B9: 250000 | C9: 73 | D9: =INT((C9-1)/12)+1 -> 7 | E9: 0.0575
A10: Total | B10: =SUM(B4:B9) -> 1250000
A12: ACQUISITION COST
A13: Acquisition price ($/SF) | B13: 95
A14: Build-out + modular partitions ($/SF) | B14: 22
A15: Soft costs (% of hard cost) | B15: 0.0275
A17: FINANCING
A18: Senior debt (% of total cost, LTC) | B18: 0.65
A19: LP equity (% of equity) | B19: 0.8
A20: GP equity (% of equity) | B20: 0.2
A22: REVENUE
A23: Blended base rent ($/SF, NNN, annual) | B23: 10.25
A24: Annual rent escalation | B24: 0.03
A25: Stabilized occupancy | B25: 0.9
A26: Lease-up ramp to stabilized (months) | B26: 36
A27: Starter bays (% of each building) | B27: 0.05
A28: Starter-bay rent discount | B28: 0.3
A29: Other income ($/SF, yr 3+) | B29: 0.15
A31: OPERATING EXPENSES
A32: Property opex ($/SF: tax, ins, CAM, maint) | B32: 3.5
A33: Opex recovery (% via NNN) | B33: 0.95
A34: Property management (% of revenue) | B34: 0.03
A35: Corporate G&A, year 1 ($) | B35: 300000
A36: G&A per added building ($/yr) | B36: 75000
A37: Marketing base ($/yr) | B37: 20000
A38: Marketing per lease-up building ($/yr) | B38: 10000
A39: Leasing commission (% of lease value) | B39: 0.05
A40: Capital reserves ($/SF/yr) | B40: 0.15
A42: EXIT
A43: Exit cap rate | B43: 0.065
A44: Selling costs (% of value) | B44: 0.025
A45: Hold period (years) | B45: 10

Sheet Acq & Financing
A1: Acquisition & Financing (per building, $)
A3: Building | B3: Size (SF) | C3: Acq. Month | D3: Total Cost | E3: Senior Debt | F3: Equity | G3: Debt Rate | H3: LP Equity | I3: GP Equity
A4: =Assumptions!A4 -> Flagship (Bldg 1) | B4: =Assumptions!B4 -> 175000 | C4: =Assumptions!C4 -> 1 | D4: =Assumptions!B4*(Assumptions!$B$13+Assumptions!$B$14)*(1+Assumptions!$B$15) -> 21038062 | E4: =Assumptions!$B$18*D4 -> 13674741 | F4: =D4-E4 -> 7363321.9 | G4: =Assumptions!E4 -> 0.0675 | H4: =F4*Assumptions!$B$19 -> 5890657.5 | I4: =F4*Assumptions!$B$20 -> 1472664.4
A5: =Assumptions!A5 -> Building 2 | B5: =Assumptions!B5 -> 175000 | C5: =Assumptions!C5 -> 25 | D5: =Assumptions!B5*(Assumptions!$B$13+Assumptions!$B$14)*(1+Assumptions!$B$15) -> 21038062 | E5: =Assumptions!$B$18*D5 -> 13674741 | F5: =D5-E5 -> 7363321.9 | G5: =Assumptions!E5 -> 0.0675 | H5: =F5*Assumptions!$B$19 -> 5890657.5 | I5: =F5*Assumptions!$B$20 -> 1472664.4
A6: =Assumptions!A6 -> Building 3 | B6: =Assumptions!B6 -> 150000 | C6: =Assumptions!C6 -> 37 | D6: =Assumptions!B6*(Assumptions!$B$13+Assumptions!$B$14)*(1+Assumptions!$B$15) -> 18032625 | E6: =Assumptions!$B$18*D6 -> 11721206 | F6: =D6-E6 -> 6311418.8 | G6: =Assumptions!E6 -> 0.06 | H6: =F6*Assumptions!$B$19 -> 5049135 | I6: =F6*Assumptions!$B$20 -> 1262283.8
A7: =Assumptions!A7 -> Building 4 | B7: =Assumptions!B7 -> 250000 | C7: =Assumptions!C7 -> 49 | D7: =Assumptions!B7*(Assumptions!$B$13+Assumptions!$B$14)*(1+Assumptions!$B$15) -> 30054375 | E7: =Assumptions!$B$18*D7 -> 19535344 | F7: =D7-E7 -> 10519031 | G7: =Assumptions!E7 -> 0.06 | H7: =F7*Assumptions!$B$19 -> 8415225 | I7: =F7*Assumptions!$B$20 -> 2103806.2
A8: =Assumptions!A8 -> Building 5 | B8: =Assumptions!B8 -> 250000 | C8: =Assumptions!C8 -> 61 | D8: =Assumptions!B8*(Assumptions!$B$13+Assumptions!$B$14)*(1+Assumptions!$B$15) -> 30054375 | E8: =Assumptions!$B$18*D8 -> 19535344 | F8: =D8-E8 -> 10519031 | G8: =Assumptions!E8 -> 0.0575 | H8: =F8*Assumptions!$B$19 -> 8415225 | I8: =F8*Assumptions!$B$20 -> 2103806.2
A9: =Assumptions!A9 -> Building 6 | B9: =Assumptions!B9 -> 250000 | C9: =Assumptions!C9 -> 73 | D9: =Assumptions!B9*(Assumptions!$B$13+Assumptions!$B$14)*(1+Assumptions!$B$15) -> 30054375 | E9: =Assumptions!$B$18*D9 -> 19535344 | F9: =D9-E9 -> 10519031 | G9: =Assumptions!E9 -> 0.0575 | H9: =F9*Assumptions!$B$19 -> 8415225 | I9: =F9*Assumptions!$B$20 -> 2103806.2
A10: Portfolio Total | B10: =SUM(B4:B9) -> 1250000 | D10: =SUM(D4:D9) -> 150271875 | E10: =SUM(E4:E9) -> 97676719 | F10: =SUM(F4:F9) -> 52595156 | H10: =SUM(H4:H9) -> 42076125 | I10: =SUM(I4:I9) -> 10519031

Sheet Operating Model
A1: Operating Model - Revenue, Pro Forma & Returns (monthly, $)
A2: Month # | C2: 1 | D2: 2 | E2: 3 | F2: 4 | G2: 5 | H2: 6 | I2: 7 | J2: 8 | K2: 9 | L2: 10 | M2: 11 | N2: 12 | O2: 13 | P2: 14 | Q2: 15 | R2: 16 | S2: 17 | T2: 18 | U2: 19 | V2: 20 | W2: 21 | X2: 22 | Y2: 23 | Z2: 24 | AA2: 25 | AB2: 26 | AC2: 27 | AD2: 28 | AE2: 29 | AF2: 30 | AG2: 31 | AH2: 32 | AI2: 33 | AJ2: 34 | AK2: 35 | AL2: 36 | AM2: 37 | AN2: 38 | AO2: 39 | AP2: 40 | AQ2: 41 | AR2: 42 | AS2: 43 | AT2: 44 | AU2: 45 | AV2: 46 | AW2: 47 | AX2: 48 | AY2: 49 | AZ2: 50 | BA2: 51 | BB2: 52 | BC2: 53 | BD2: 54 | BE2: 55 | BF2: 56 | BG2: 57 | BH2: 58 | BI2: 59 | BJ2: 60 | BK2: 61 | BL2: 62 | BM2: 63 | BN2: 64 | BO2: 65 | BP2: 66 | BQ2: 67 | BR2: 68 | BS2: 69 | BT2: 70 | BU2: 71 | BV2: 72 | BW2: 73 | BX2: 74 | BY2: 75 | BZ2: 76 | CA2: 77 | CB2: 78 | CC2: 79 | CD2: 80 | CE2: 81 | CF2: 82 | CG2: 83 | CH2: 84 | CI2: 85 | CJ2: 86 | CK2: 87 | CL2: 88 | CM2: 89 | CN2: 90 | CO2: 91 | CP2: 92 | CQ2: 93 | CR2: 94 | CS2: 95 | CT2: 96 | CU2: 97 | CV2: 98 | CW2: 99 | CX2: 100 | CY2: 101 | CZ2: 102 | DA2: 103 | DB2: 104 | DC2: 105 | DD2: 106 | DE2: 107 | DF2: 108 | DG2: 109 | DH2: 110 | DI2: 111 | DJ2: 112 | DK2: 113 | DL2: 114 | DM2: 115 | DN2: 116 | DO2: 117 | DP2: 118 | DQ2: 119 | DR2: 120
A3: Year | C3: =ROUNDUP(C2/12,0) -> 1 | D3: =ROUNDUP(D2/12,0) -> 1 | E3: =ROUNDUP(E2/12,0) -> 1 | F3: =ROUNDUP(F2/12,0) -> 1 | G3: =ROUNDUP(G2/12,0) -> 1 | H3: =ROUNDUP(H2/12,0) -> 1 | I3: =ROUNDUP(I2/12,0) -> 1 | J3: =ROUNDUP(J2/12,0) -> 1 | ... DR3: =ROUNDUP(DR2/12,0) -> 10
A4: Lease-up curve (occ by op-month) | C4: =MIN(Assumptions!$B$25,Assumptions!$B$25*C2/Assumptions!$B$26) -> 0.025 | D4: =MIN(Assumptions!$B$25,Assumptions!$B$25*D2/Assumptions!$B$26) -> 0.05 | E4: =MIN(Assumptions!$B$25,Assumptions!$B$25*E2/Assumptions!$B$26) -> 0.075 | F4: =MIN(Assumptions!$B$25,Assumptions!$B$25*F2/Assumptions!$B$26) -> 0.1 | G4: =MIN(Assumptions!$B$25,Assumptions!$B$25*G2/Assumptions!$B$26) -> 0.125 | H4: =MIN(Assumptions!$B$25,Assumptions!$B$25*H2/Assumptions!$B$26) -> 0.15 | I4: =MIN(Assumptions!$B$25,Assumptions!$B$25*I2/Assumptions!$B$26) -> 0.175 | J4: =MIN(Assumptions!$B$25,Assumptions!$B$25*J2/Assumptions!$B$26) -> 0.2 | ... DR4: =MIN(Assumptions!$B$25,Assumptions!$B$25*DR2/Assumptions!$B$26) -> 0.9
A5: Rent $/SF (monthly, escalated) | C5: =Assumptions!$B$23*(1+Assumptions!$B$24)^(C3-1)/12 -> 0.85416667 | D5: =Assumptions!$B$23*(1+Assumptions!$B$24)^(D3-1)/12 -> 0.85416667 | E5: =Assumptions!$B$23*(1+Assumptions!$B$24)^(E3-1)/12 -> 0.85416667 | F5: =Assumptions!$B$23*(1+Assumptions!$B$24)^(F3-1)/12 -> 0.85416667 | G5: =Assumptions!$B$23*(1+Assumptions!$B$24)^(G3-1)/12 -> 0.85416667 | H5: =Assumptions!$B$23*(1+Assumptions!$B$24)^(H3-1)/12 -> 0.85416667 | I5: =Assumptions!$B$23*(1+Assumptions!$B$24)^(I3-1)/12 -> 0.85416667 | J5: =Assumptions!$B$23*(1+Assumptions!$B$24)^(J3-1)/12 -> 0.85416667 | ... DR5: =Assumptions!$B$23*(1+Assumptions!$B$24)^(DR3-1)/12 -> 1.1144938
A6: Owned SF (portfolio) | C6: =SUMPRODUCT((Assumptions!$C$4:$C$9<=C2)*Assumptions!$B$4:$B$9) -> 175000 | D6: =SUMPRODUCT((Assumptions!$C$4:$C$9<=D2)*Assumptions!$B$4:$B$9) -> 175000 | E6: =SUMPRODUCT((Assumptions!$C$4:$C$9<=E2)*Assumptions!$B$4:$B$9) -> 175000 | F6: =SUMPRODUCT((Assumptions!$C$4:$C$9<=F2)*Assumptions!$B$4:$B$9) -> 175000 | G6: =SUMPRODUCT((Assumptions!$C$4:$C$9<=G2)*Assumptions!$B$4:$B$9) -> 175000 | H6: =SUMPRODUCT((Assumptions!$C$4:$C$9<=H2)*Assumptions!$B$4:$B$9) -> 175000 | I6: =SUMPRODUCT((Assumptions!$C$4:$C$9<=I2)*Assumptions!$B$4:$B$9) -> 175000 | J6: =SUMPRODUCT((Assumptions!$C$4:$C$9<=J2)*Assumptions!$B$4:$B$9) -> 175000 | ... DR6: =SUMPRODUCT((Assumptions!$C$4:$C$9<=DR2)*Assumptions!$B$4:$B$9) -> 1250000
A7: REVENUE BUILD
A8: Flagship (Bldg 1) -- Occupied SF | C8: =IF((C$2-Assumptions!$C$4+1)<1,0,Assumptions!$B$4*INDEX($C$4:$DR$4,1,C$2-Assumptions!$C$4+1)) -> 4375 | D8: =IF((D$2-Assumptions!$C$4+1)<1,0,Assumptions!$B$4*INDEX($C$4:$DR$4,1,D$2-Assumptions!$C$4+1)) -> 8750 | E8: =IF((E$2-Assumptions!$C$4+1)<1,0,Assumptions!$B$4*INDEX($C$4:$DR$4,1,E$2-Assumptions!$C$4+1)) -> 13125 | F8: =IF((F$2-Assumptions!$C$4+1)<1,0,Assumptions!$B$4*INDEX($C$4:$DR$4,1,F$2-Assumptions!$C$4+1)) -> 17500 | G8: =IF((G$2-Assumptions!$C$4+1)<1,0,Assumptions!$B$4*INDEX($C$4:$DR$4,1,G$2-Assumptions!$C$4+1)) -> 21875 | H8: =IF((H$2-Assumptions!$C$4+1)<1,0,Assumptions!$B$4*INDEX($C$4:$DR$4,1,H$2-Assumptions!$C$4+1)) -> 26250 | I8: =IF((I$2-Assumptions!$C$4+1)<1,0,Assumptions!$B$4*INDEX($C$4:$DR$4,1,I$2-Assumptions!$C$4+1)) -> 30625 | J8: =IF((J$2-Assumptions!$C$4+1)<1,0,Assumptions!$B$4*INDEX($C$4:$DR$4,1,J$2-Assumptions!$C$4+1)) -> 35000 | ... DR8: =IF((DR$2-Assumptions!$C$4+1)<1,0,Assumptions!$B$4*INDEX($C$4:$DR$4,1,DR$2-Assumptions!$C$4+1)) -> 157500
A9: Building 2 -- Occupied SF | C9: =IF((C$2-Assumptions!$C$5+1)<1,0,Assumptions!$B$5*INDEX($C$4:$DR$4,1,C$2-Assumptions!$C$5+1)) -> 0 | D9: =IF((D$2-Assumptions!$C$5+1)<1,0,Assumptions!$B$5*INDEX($C$4:$DR$4,1,D$2-Assumptions!$C$5+1)) -> 0 | E9: =IF((E$2-Assumptions!$C$5+1)<1,0,Assumptions!$B$5*INDEX($C$4:$DR$4,1,E$2-Assumptions!$C$5+1)) -> 0 | F9: =IF((F$2-Assumptions!$C$5+1)<1,0,Assumptions!$B$5*INDEX($C$4:$DR$4,1,F$2-Assumptions!$C$5+1)) -> 0 | G9: =IF((G$2-Assumptions!$C$5+1)<1,0,Assumptions!$B$5*INDEX($C$4:$DR$4,1,G$2-Assumptions!$C$5+1)) -> 0 | H9: =IF((H$2-Assumptions!$C$5+1)<1,0,Assumptions!$B$5*INDEX($C$4:$DR$4,1,H$2-Assumptions!$C$5+1)) -> 0 | I9: =IF((I$2-Assumptions!$C$5+1)<1,0,Assumptions!$B$5*INDEX($C$4:$DR$4,1,I$2-Assumptions!$C$5+1)) -> 0 | J9: =IF((J$2-Assumptions!$C$5+1)<1,0,Assumptions!$B$5*INDEX($C$4:$DR$4,1,J$2-Assumptions!$C$5+1)) -> 0 | ... DR9: =IF((DR$2-Assumptions!$C$5+1)<1,0,Assumptions!$B$5*INDEX($C$4:$DR$4,1,DR$2-Assumptions!$C$5+1)) -> 157500
A10: Building 3 -- Occupied SF | C10: =IF((C$2-Assumptions!$C$6+1)<1,0,Assumptions!$B$6*INDEX($C$4:$DR$4,1,C$2-Assumptions!$C$6+1)) -> 0 | D10: =IF((D$2-Assumptions!$C$6+1)<1,0,Assumptions!$B$6*INDEX($C$4:$DR$4,1,D$2-Assumptions!$C$6+1)) -> 0 | E10: =IF((E$2-Assumptions!$C$6+1)<1,0,Assumptions!$B$6*INDEX($C$4:$DR$4,1,E$2-Assumptions!$C$6+1)) -> 0 | F10: =IF((F$2-Assumptions!$C$6+1)<1,0,Assumptions!$B$6*INDEX($C$4:$DR$4,1,F$2-Assumptions!$C$6+1)) -> 0 | G10: =IF((G$2-Assumptions!$C$6+1)<1,0,Assumptions!$B$6*INDEX($C$4:$DR$4,1,G$2-Assumptions!$C$6+1)) -> 0 | H10: =IF((H$2-Assumptions!$C$6+1)<1,0,Assumptions!$B$6*INDEX($C$4:$DR$4,1,H$2-Assumptions!$C$6+1)) -> 0 | I10: =IF((I$2-Assumptions!$C$6+1)<1,0,Assumptions!$B$6*INDEX($C$4:$DR$4,1,I$2-Assumptions!$C$6+1)) -> 0 | J10: =IF((J$2-Assumptions!$C$6+1)<1,0,Assumptions!$B$6*INDEX($C$4:$DR$4,1,J$2-Assumptions!$C$6+1)) -> 0 | ... DR10: =IF((DR$2-Assumptions!$C$6+1)<1,0,Assumptions!$B$6*INDEX($C$4:$DR$4,1,DR$2-Assumptions!$C$6+1)) -> 135000
A11: Building 4 -- Occupied SF | C11: =IF((C$2-Assumptions!$C$7+1)<1,0,Assumptions!$B$7*INDEX($C$4:$DR$4,1,C$2-Assumptions!$C$7+1)) -> 0 | D11: =IF((D$2-Assumptions!$C$7+1)<1,0,Assumptions!$B$7*INDEX($C$4:$DR$4,1,D$2-Assumptions!$C$7+1)) -> 0 | E11: =IF((E$2-Assumptions!$C$7+1)<1,0,Assumptions!$B$7*INDEX($C$4:$DR$4,1,E$2-Assumptions!$C$7+1)) -> 0 | F11: =IF((F$2-Assumptions!$C$7+1)<1,0,Assumptions!$B$7*INDEX($C$4:$DR$4,1,F$2-Assumptions!$C$7+1)) -> 0 | G11: =IF((G$2-Assumptions!$C$7+1)<1,0,Assumptions!$B$7*INDEX($C$4:$DR$4,1,G$2-Assumptions!$C$7+1)) -> 0 | H11: =IF((H$2-Assumptions!$C$7+1)<1,0,Assumptions!$B$7*INDEX($C$4:$DR$4,1,H$2-Assumptions!$C$7+1)) -> 0 | I11: =IF((I$2-Assumptions!$C$7+1)<1,0,Assumptions!$B$7*INDEX($C$4:$DR$4,1,I$2-Assumptions!$C$7+1)) -> 0 | J11: =IF((J$2-Assumptions!$C$7+1)<1,0,Assumptions!$B$7*INDEX($C$4:$DR$4,1,J$2-Assumptions!$C$7+1)) -> 0 | ... DR11: =IF((DR$2-Assumptions!$C$7+1)<1,0,Assumptions!$B$7*INDEX($C$4:$DR$4,1,DR$2-Assumptions!$C$7+1)) -> 225000
A12: Building 5 -- Occupied SF | C12: =IF((C$2-Assumptions!$C$8+1)<1,0,Assumptions!$B$8*INDEX($C$4:$DR$4,1,C$2-Assumptions!$C$8+1)) -> 0 | D12: =IF((D$2-Assumptions!$C$8+1)<1,0,Assumptions!$B$8*INDEX($C$4:$DR$4,1,D$2-Assumptions!$C$8+1)) -> 0 | E12: =IF((E$2-Assumptions!$C$8+1)<1,0,Assumptions!$B$8*INDEX($C$4:$DR$4,1,E$2-Assumptions!$C$8+1)) -> 0 | F12: =IF((F$2-Assumptions!$C$8+1)<1,0,Assumptions!$B$8*INDEX($C$4:$DR$4,1,F$2-Assumptions!$C$8+1)) -> 0 | G12: =IF((G$2-Assumptions!$C$8+1)<1,0,Assumptions!$B$8*INDEX($C$4:$DR$4,1,G$2-Assumptions!$C$8+1)) -> 0 | H12: =IF((H$2-Assumptions!$C$8+1)<1,0,Assumptions!$B$8*INDEX($C$4:$DR$4,1,H$2-Assumptions!$C$8+1)) -> 0 | I12: =IF((I$2-Assumptions!$C$8+1)<1,0,Assumptions!$B$8*INDEX($C$4:$DR$4,1,I$2-Assumptions!$C$8+1)) -> 0 | J12: =IF((J$2-Assumptions!$C$8+1)<1,0,Assumptions!$B$8*INDEX($C$4:$DR$4,1,J$2-Assumptions!$C$8+1)) -> 0 | ... DR12: =IF((DR$2-Assumptions!$C$8+1)<1,0,Assumptions!$B$8*INDEX($C$4:$DR$4,1,DR$2-Assumptions!$C$8+1)) -> 225000
A13: Building 6 -- Occupied SF | C13: =IF((C$2-Assumptions!$C$9+1)<1,0,Assumptions!$B$9*INDEX($C$4:$DR$4,1,C$2-Assumptions!$C$9+1)) -> 0 | D13: =IF((D$2-Assumptions!$C$9+1)<1,0,Assumptions!$B$9*INDEX($C$4:$DR$4,1,D$2-Assumptions!$C$9+1)) -> 0 | E13: =IF((E$2-Assumptions!$C$9+1)<1,0,Assumptions!$B$9*INDEX($C$4:$DR$4,1,E$2-Assumptions!$C$9+1)) -> 0 | F13: =IF((F$2-Assumptions!$C$9+1)<1,0,Assumptions!$B$9*INDEX($C$4:$DR$4,1,F$2-Assumptions!$C$9+1)) -> 0 | G13: =IF((G$2-Assumptions!$C$9+1)<1,0,Assumptions!$B$9*INDEX($C$4:$DR$4,1,G$2-Assumptions!$C$9+1)) -> 0 | H13: =IF((H$2-Assumptions!$C$9+1)<1,0,Assumptions!$B$9*INDEX($C$4:$DR$4,1,H$2-Assumptions!$C$9+1)) -> 0 | I13: =IF((I$2-Assumptions!$C$9+1)<1,0,Assumptions!$B$9*INDEX($C$4:$DR$4,1,I$2-Assumptions!$C$9+1)) -> 0 | J13: =IF((J$2-Assumptions!$C$9+1)<1,0,Assumptions!$B$9*INDEX($C$4:$DR$4,1,J$2-Assumptions!$C$9+1)) -> 0 | ... DR13: =IF((DR$2-Assumptions!$C$9+1)<1,0,Assumptions!$B$9*INDEX($C$4:$DR$4,1,DR$2-Assumptions!$C$9+1)) -> 225000
A15: Occupied SF (portfolio) | C15: =SUM(C8:C13) -> 4375 | D15: =SUM(D8:D13) -> 8750 | E15: =SUM(E8:E13) -> 13125 | F15: =SUM(F8:F13) -> 17500 | G15: =SUM(G8:G13) -> 21875 | H15: =SUM(H8:H13) -> 26250 | I15: =SUM(I8:I13) -> 30625 | J15: =SUM(J8:J13) -> 35000 | ... DR15: =SUM(DR8:DR13) -> 1125000
A16: Occupancy % | C16: =IF(C6=0,0,C15/C6) -> 0.025 | D16: =IF(D6=0,0,D15/D6) -> 0.05 | E16: =IF(E6=0,0,E15/E6) -> 0.075 | F16: =IF(F6=0,0,F15/F6) -> 0.1 | G16: =IF(G6=0,0,G15/G6) -> 0.125 | H16: =IF(H6=0,0,H15/H6) -> 0.15 | I16: =IF(I6=0,0,I15/I6) -> 0.175 | J16: =IF(J6=0,0,J15/J6) -> 0.2 | ... DR16: =IF(DR6=0,0,DR15/DR6) -> 0.9
A18: Flagship (Bldg 1) -- Revenue | C18: =C8*(C$5*(1-Assumptions!$B$27*Assumptions!$B$28)+IF(C$3>=3,Assumptions!$B$29/12,0)) -> 3680.9245 | D18: =D8*(D$5*(1-Assumptions!$B$27*Assumptions!$B$28)+IF(D$3>=3,Assumptions!$B$29/12,0)) -> 7361.849 | E18: =E8*(E$5*(1-Assumptions!$B$27*Assumptions!$B$28)+IF(E$3>=3,Assumptions!$B$29/12,0)) -> 11042.773 | F18: =F8*(F$5*(1-Assumptions!$B$27*Assumptions!$B$28)+IF(F$3>=3,Assumptions!$B$29/12,0)) -> 14723.698 | G18: =G8*(G$5*(1-Assumptions!$B$27*Assumptions!$B$28)+IF(G$3>=3,Assumptions!$B$29/12,0)) -> 18404.622 | H18: =H8*(H$5*(1-Assumptions!$B$27*Assumptions!$B$28)+IF(H$3>=3,Assumptions!$B$29/12,0)) -> 22085.547 | I18: =I8*(I$5*(1-Assumptions!$B$27*Assumptions!$B$28)+IF(I$3>=3,Assumptions!$B$29/12,0)) -> 25766.471 | J18: =J8*(J$5*(1-Assumptions!$B$27*Assumptions!$B$28)+IF(J$3>=3,Assumptions!$B$29/12,0)) -> 29447.396 | ... DR18: =DR8*(DR$5*(1-Assumptions!$B$27*Assumptions!$B$28)+IF(DR$3>=3,Assumptions!$B$29/12,0)) -> 174868.53
A19: Building 2 -- Revenue | C19: =C9*(C$5*(1-Assumptions!$B$27*Assumptions!$B$28)+IF(C$3>=3,Assumptions!$B$29/12,0)) -> 0 | D19: =D9*(D$5*(1-Assumptions!$B$27*Assumptions!$B$28)+IF(D$3>=3,Assumptions!$B$29/12,0)) -> 0 | E19: =E9*(E$5*(1-Assumptions!$B$27*Assumptions!$B$28)+IF(E$3>=3,Assumptions!$B$29/12,0)) -> 0 | F19: =F9*(F$5*(1-Assumptions!$B$27*Assumptions!$B$28)+IF(F$3>=3,Assumptions!$B$29/12,0)) -> 0 | G19: =G9*(G$5*(1-Assumptions!$B$27*Assumptions!$B$28)+IF(G$3>=3,Assumptions!$B$29/12,0)) -> 0 | H19: =H9*(H$5*(1-Assumptions!$B$27*Assumptions!$B$28)+IF(H$3>=3,Assumptions!$B$29/12,0)) -> 0 | I19: =I9*(I$5*(1-Assumptions!$B$27*Assumptions!$B$28)+IF(I$3>=3,Assumptions!$B$29/12,0)) -> 0 | J19: =J9*(J$5*(1-Assumptions!$B$27*Assumptions!$B$28)+IF(J$3>=3,Assumptions!$B$29/12,0)) -> 0 | ... DR19: =DR9*(DR$5*(1-Assumptions!$B$27*Assumptions!$B$28)+IF(DR$3>=3,Assumptions!$B$29/12,0)) -> 174868.53
A20: Building 3 -- Revenue | C20: =C10*(C$5*(1-Assumptions!$B$27*Assumptions!$B$28)+IF(C$3>=3,Assumptions!$B$29/12,0)) -> 0 | D20: =D10*(D$5*(1-Assumptions!$B$27*Assumptions!$B$28)+IF(D$3>=3,Assumptions!$B$29/12,0)) -> 0 | E20: =E10*(E$5*(1-Assumptions!$B$27*Assumptions!$B$28)+IF(E$3>=3,Assumptions!$B$29/12,0)) -> 0 | F20: =F10*(F$5*(1-Assumptions!$B$27*Assumptions!$B$28)+IF(F$3>=3,Assumptions!$B$29/12,0)) -> 0 | G20: =G10*(G$5*(1-Assumptions!$B$27*Assumptions!$B$28)+IF(G$3>=3,Assumptions!$B$29/12,0)) -> 0 | H20: =H10*(H$5*(1-Assumptions!$B$27*Assumptions!$B$28)+IF(H$3>=3,Assumptions!$B$29/12,0)) -> 0 | I20: =I10*(I$5*(1-Assumptions!$B$27*Assumptions!$B$28)+IF(I$3>=3,Assumptions!$B$29/12,0)) -> 0 | J20: =J10*(J$5*(1-Assumptions!$B$27*Assumptions!$B$28)+IF(J$3>=3,Assumptions!$B$29/12,0)) -> 0 | ... DR20: =DR10*(DR$5*(1-Assumptions!$B$27*Assumptions!$B$28)+IF(DR$3>=3,Assumptions!$B$29/12,0)) -> 149887.31
A21: Building 4 -- Revenue | C21: =C11*(C$5*(1-Assumptions!$B$27*Assumptions!$B$28)+IF(C$3>=3,Assumptions!$B$29/12,0)) -> 0 | D21: =D11*(D$5*(1-Assumptions!$B$27*Assumptions!$B$28)+IF(D$3>=3,Assumptions!$B$29/12,0)) -> 0 | E21: =E11*(E$5*(1-Assumptions!$B$27*Assumptions!$B$28)+IF(E$3>=3,Assumptions!$B$29/12,0)) -> 0 | F21: =F11*(F$5*(1-Assumptions!$B$27*Assumptions!$B$28)+IF(F$3>=3,Assumptions!$B$29/12,0)) -> 0 | G21: =G11*(G$5*(1-Assumptions!$B$27*Assumptions!$B$28)+IF(G$3>=3,Assumptions!$B$29/12,0)) -> 0 | H21: =H11*(H$5*(1-Assumptions!$B$27*Assumptions!$B$28)+IF(H$3>=3,Assumptions!$B$29/12,0)) -> 0 | I21: =I11*(I$5*(1-Assumptions!$B$27*Assumptions!$B$28)+IF(I$3>=3,Assumptions!$B$29/12,0)) -> 0 | J21: =J11*(J$5*(1-Assumptions!$B$27*Assumptions!$B$28)+IF(J$3>=3,Assumptions!$B$29/12,0)) -> 0 | ... DR21: =DR11*(DR$5*(1-Assumptions!$B$27*Assumptions!$B$28)+IF(DR$3>=3,Assumptions!$B$29/12,0)) -> 249812.18
A22: Building 5 -- Revenue | C22: =C12*(C$5*(1-Assumptions!$B$27*Assumptions!$B$28)+IF(C$3>=3,Assumptions!$B$29/12,0)) -> 0 | D22: =D12*(D$5*(1-Assumptions!$B$27*Assumptions!$B$28)+IF(D$3>=3,Assumptions!$B$29/12,0)) -> 0 | E22: =E12*(E$5*(1-Assumptions!$B$27*Assumptions!$B$28)+IF(E$3>=3,Assumptions!$B$29/12,0)) -> 0 | F22: =F12*(F$5*(1-Assumptions!$B$27*Assumptions!$B$28)+IF(F$3>=3,Assumptions!$B$29/12,0)) -> 0 | G22: =G12*(G$5*(1-Assumptions!$B$27*Assumptions!$B$28)+IF(G$3>=3,Assumptions!$B$29/12,0)) -> 0 | H22: =H12*(H$5*(1-Assumptions!$B$27*Assumptions!$B$28)+IF(H$3>=3,Assumptions!$B$29/12,0)) -> 0 | I22: =I12*(I$5*(1-Assumptions!$B$27*Assumptions!$B$28)+IF(I$3>=3,Assumptions!$B$29/12,0)) -> 0 | J22: =J12*(J$5*(1-Assumptions!$B$27*Assumptions!$B$28)+IF(J$3>=3,Assumptions!$B$29/12,0)) -> 0 | ... DR22: =DR12*(DR$5*(1-Assumptions!$B$27*Assumptions!$B$28)+IF(DR$3>=3,Assumptions!$B$29/12,0)) -> 249812.18
A23: Building 6 -- Revenue | C23: =C13*(C$5*(1-Assumptions!$B$27*Assumptions!$B$28)+IF(C$3>=3,Assumptions!$B$29/12,0)) -> 0 | D23: =D13*(D$5*(1-Assumptions!$B$27*Assumptions!$B$28)+IF(D$3>=3,Assumptions!$B$29/12,0)) -> 0 | E23: =E13*(E$5*(1-Assumptions!$B$27*Assumptions!$B$28)+IF(E$3>=3,Assumptions!$B$29/12,0)) -> 0 | F23: =F13*(F$5*(1-Assumptions!$B$27*Assumptions!$B$28)+IF(F$3>=3,Assumptions!$B$29/12,0)) -> 0 | G23: =G13*(G$5*(1-Assumptions!$B$27*Assumptions!$B$28)+IF(G$3>=3,Assumptions!$B$29/12,0)) -> 0 | H23: =H13*(H$5*(1-Assumptions!$B$27*Assumptions!$B$28)+IF(H$3>=3,Assumptions!$B$29/12,0)) -> 0 | I23: =I13*(I$5*(1-Assumptions!$B$27*Assumptions!$B$28)+IF(I$3>=3,Assumptions!$B$29/12,0)) -> 0 | J23: =J13*(J$5*(1-Assumptions!$B$27*Assumptions!$B$28)+IF(J$3>=3,Assumptions!$B$29/12,0)) -> 0 | ... DR23: =DR13*(DR$5*(1-Assumptions!$B$27*Assumptions!$B$28)+IF(DR$3>=3,Assumptions!$B$29/12,0)) -> 249812.18
A25: PORTFOLIO REVENUE (EGI) | C25: =SUM(C18:C23) -> 3680.9245 | D25: =SUM(D18:D23) -> 7361.849 | E25: =SUM(E18:E23) -> 11042.773 | F25: =SUM(F18:F23) -> 14723.698 | G25: =SUM(G18:G23) -> 18404.622 | H25: =SUM(H18:H23) -> 22085.547 | I25: =SUM(I18:I23) -> 25766.471 | J25: =SUM(J18:J23) -> 29447.396 | ... DR25: =SUM(DR18:DR23) -> 1249060.9
A26: OPERATING PRO FORMA
A27: Property opex (net of NNN recovery) | C27: =Assumptions!$B$32/12*C6*(1-Assumptions!$B$33*C16) -> 49829.427 | D27: =Assumptions!$B$32/12*D6*(1-Assumptions!$B$33*D16) -> 48617.188 | E27: =Assumptions!$B$32/12*E6*(1-Assumptions!$B$33*E16) -> 47404.948 | F27: =Assumptions!$B$32/12*F6*(1-Assumptions!$B$33*F16) -> 46192.708 | G27: =Assumptions!$B$32/12*G6*(1-Assumptions!$B$33*G16) -> 44980.469 | H27: =Assumptions!$B$32/12*H6*(1-Assumptions!$B$33*H16) -> 43768.229 | I27: =Assumptions!$B$32/12*I6*(1-Assumptions!$B$33*I16) -> 42555.99 | J27: =Assumptions!$B$32/12*J6*(1-Assumptions!$B$33*J16) -> 41343.75 | ... DR27: =Assumptions!$B$32/12*DR6*(1-Assumptions!$B$33*DR16) -> 52864.583
A28: Property management | C28: =Assumptions!$B$34*C25 -> 110.42773 | D28: =Assumptions!$B$34*D25 -> 220.85547 | E28: =Assumptions!$B$34*E25 -> 331.2832 | F28: =Assumptions!$B$34*F25 -> 441.71094 | G28: =Assumptions!$B$34*G25 -> 552.13867 | H28: =Assumptions!$B$34*H25 -> 662.56641 | I28: =Assumptions!$B$34*I25 -> 772.99414 | J28: =Assumptions!$B$34*J25 -> 883.42187 | ... DR28: =Assumptions!$B$34*DR25 -> 37471.827
A29: NET OPERATING INCOME (NOI) | C29: =C25-C27-C28 -> -46258.93 | D29: =D25-D27-D28 -> -41476.194 | E29: =E25-E27-E28 -> -36693.458 | F29: =F25-F27-F28 -> -31910.721 | G29: =G25-G27-G28 -> -27127.985 | H29: =H25-H27-H28 -> -22345.249 | I29: =I25-I27-I28 -> -17562.512 | J29: =J25-J27-J28 -> -12779.776 | ... DR29: =DR25-DR27-DR28 -> 1158724.5
A30: Buildings owned | C30: =COUNTIF(Assumptions!$C$4:$C$9,"<="&C2) -> 1 | D30: =COUNTIF(Assumptions!$C$4:$C$9,"<="&D2) -> 1 | E30: =COUNTIF(Assumptions!$C$4:$C$9,"<="&E2) -> 1 | F30: =COUNTIF(Assumptions!$C$4:$C$9,"<="&F2) -> 1 | G30: =COUNTIF(Assumptions!$C$4:$C$9,"<="&G2) -> 1 | H30: =COUNTIF(Assumptions!$C$4:$C$9,"<="&H2) -> 1 | I30: =COUNTIF(Assumptions!$C$4:$C$9,"<="&I2) -> 1 | J30: =COUNTIF(Assumptions!$C$4:$C$9,"<="&J2) -> 1 | ... DR30: =COUNTIF(Assumptions!$C$4:$C$9,"<="&DR2) -> 6
A31: Buildings in lease-up | C31: =COUNTIFS(Assumptions!$C$4:$C$9,"<="&C2,Assumptions!$C$4:$C$9,">"&(C2-Assumptions!$B$26)) -> 1 | D31: =COUNTIFS(Assumptions!$C$4:$C$9,"<="&D2,Assumptions!$C$4:$C$9,">"&(D2-Assumptions!$B$26)) -> 1 | E31: =COUNTIFS(Assumptions!$C$4:$C$9,"<="&E2,Assumptions!$C$4:$C$9,">"&(E2-Assumptions!$B$26)) -> 1 | F31: =COUNTIFS(Assumptions!$C$4:$C$9,"<="&F2,Assumptions!$C$4:$C$9,">"&(F2-Assumptions!$B$26)) -> 1 | G31: =COUNTIFS(Assumptions!$C$4:$C$9,"<="&G2,Assumptions!$C$4:$C$9,">"&(G2-Assumptions!$B$26)) -> 1 | H31: =COUNTIFS(Assumptions!$C$4:$C$9,"<="&H2,Assumptions!$C$4:$C$9,">"&(H2-Assumptions!$B$26)) -> 1 | I31: =COUNTIFS(Assumptions!$C$4:$C$9,"<="&I2,Assumptions!$C$4:$C$9,">"&(I2-Assumptions!$B$26)) -> 1 | J31: =COUNTIFS(Assumptions!$C$4:$C$9,"<="&J2,Assumptions!$C$4:$C$9,">"&(J2-Assumptions!$B$26)) -> 1 | ... DR31: =COUNTIFS(Assumptions!$C$4:$C$9,"<="&DR2,Assumptions!$C$4:$C$9,">"&(DR2-Assumptions!$B$26)) -> 0
A32: Corporate G&A | C32: =(Assumptions!$B$35+Assumptions!$B$36*MAX(0,C30-1))/12 -> 25000 | D32: =(Assumptions!$B$35+Assumptions!$B$36*MAX(0,D30-1))/12 -> 25000 | E32: =(Assumptions!$B$35+Assumptions!$B$36*MAX(0,E30-1))/12 -> 25000 | F32: =(Assumptions!$B$35+Assumptions!$B$36*MAX(0,F30-1))/12 -> 25000 | G32: =(Assumptions!$B$35+Assumptions!$B$36*MAX(0,G30-1))/12 -> 25000 | H32: =(Assumptions!$B$35+Assumptions!$B$36*MAX(0,H30-1))/12 -> 25000 | I32: =(Assumptions!$B$35+Assumptions!$B$36*MAX(0,I30-1))/12 -> 25000 | J32: =(Assumptions!$B$35+Assumptions!$B$36*MAX(0,J30-1))/12 -> 25000 | ... DR32: =(Assumptions!$B$35+Assumptions!$B$36*MAX(0,DR30-1))/12 -> 56250
A33: Marketing | C33: =(Assumptions!$B$37+Assumptions!$B$38*C31)/12 -> 2500 | D33: =(Assumptions!$B$37+Assumptions!$B$38*D31)/12 -> 2500 | E33: =(Assumptions!$B$37+Assumptions!$B$38*E31)/12 -> 2500 | F33: =(Assumptions!$B$37+Assumptions!$B$38*F31)/12 -> 2500 | G33: =(Assumptions!$B$37+Assumptions!$B$38*G31)/12 -> 2500 | H33: =(Assumptions!$B$37+Assumptions!$B$38*H31)/12 -> 2500 | I33: =(Assumptions!$B$37+Assumptions!$B$38*I31)/12 -> 2500 | J33: =(Assumptions!$B$37+Assumptions!$B$38*J31)/12 -> 2500 | ... DR33: =(Assumptions!$B$37+Assumptions!$B$38*DR31)/12 -> 1666.6667
A34: Leasing commissions | C34: =Assumptions!$B$39*C15*C5*12 -> 2242.1875 | D34: =Assumptions!$B$39*MAX(0,D15-C15)*D5*12 -> 2242.1875 | E34: =Assumptions!$B$39*MAX(0,E15-D15)*E5*12 -> 2242.1875 | F34: =Assumptions!$B$39*MAX(0,F15-E15)*F5*12 -> 2242.1875 | G34: =Assumptions!$B$39*MAX(0,G15-F15)*G5*12 -> 2242.1875 | H34: =Assumptions!$B$39*MAX(0,H15-G15)*H5*12 -> 2242.1875 | I34: =Assumptions!$B$39*MAX(0,I15-H15)*I5*12 -> 2242.1875 | J34: =Assumptions!$B$39*MAX(0,J15-I15)*J5*12 -> 2242.1875 | K34: =Assumptions!$B$39*MAX(0,K15-J15)*K5*12 -> 2242.1875 | ... DR34: =Assumptions!$B$39*MAX(0,DR15-DQ15)*DR5*12 -> 0
A35: Capital reserves | C35: =Assumptions!$B$40/12*C6 -> 2187.5 | D35: =Assumptions!$B$40/12*D6 -> 2187.5 | E35: =Assumptions!$B$40/12*E6 -> 2187.5 | F35: =Assumptions!$B$40/12*F6 -> 2187.5 | G35: =Assumptions!$B$40/12*G6 -> 2187.5 | H35: =Assumptions!$B$40/12*H6 -> 2187.5 | I35: =Assumptions!$B$40/12*I6 -> 2187.5 | J35: =Assumptions!$B$40/12*J6 -> 2187.5 | ... DR35: =Assumptions!$B$40/12*DR6 -> 15625
A36: OPERATING PROFIT (unlevered) | C36: =C29-C32-C33-C34-C35 -> -78188.618 | D36: =D29-D32-D33-D34-D35 -> -73405.882 | E36: =E29-E32-E33-E34-E35 -> -68623.145 | F36: =F29-F32-F33-F34-F35 -> -63840.409 | G36: =G29-G32-G33-G34-G35 -> -59057.673 | H36: =H29-H32-H33-H34-H35 -> -54274.936 | I36: =I29-I32-I33-I34-I35 -> -49492.2 | J36: =J29-J32-J33-J34-J35 -> -44709.464 | ... DR36: =DR29-DR32-DR33-DR34-DR35 -> 1085182.8
A37: Interest expense | C37: {=SUMPRODUCT((Assumptions!$C$4:$C$9<=C2)*'Acq & Financing'!$E$4:$E$9*Assumptions!$E$4:$E$9)/12} -> 76920.416 | D37: =SUMPRODUCT((Assumptions!$C$4:$C$9<=D2)*'Acq & Financing'!$E$4:$E$9*Assumptions!$E$4:$E$9)/12 -> 76920.416 | E37: =SUMPRODUCT((Assumptions!$C$4:$C$9<=E2)*'Acq & Financing'!$E$4:$E$9*Assumptions!$E$4:$E$9)/12 -> 76920.416 | F37: =SUMPRODUCT((Assumptions!$C$4:$C$9<=F2)*'Acq & Financing'!$E$4:$E$9*Assumptions!$E$4:$E$9)/12 -> 76920.416 | G37: =SUMPRODUCT((Assumptions!$C$4:$C$9<=G2)*'Acq & Financing'!$E$4:$E$9*Assumptions!$E$4:$E$9)/12 -> 76920.416 | H37: =SUMPRODUCT((Assumptions!$C$4:$C$9<=H2)*'Acq & Financing'!$E$4:$E$9*Assumptions!$E$4:$E$9)/12 -> 76920.416 | I37: =SUMPRODUCT((Assumptions!$C$4:$C$9<=I2)*'Acq & Financing'!$E$4:$E$9*Assumptions!$E$4:$E$9)/12 -> 76920.416 | J37: =SUMPRODUCT((Assumptions!$C$4:$C$9<=J2)*'Acq & Financing'!$E$4:$E$9*Assumptions!$E$4:$E$9)/12 -> 76920.416 | K37: =SUMPRODUCT((Assumptions!$C$4:$C$9<=K2)*'Acq & Financing'!$E$4:$E$9*Assumptions!$E$4:$E$9)/12 -> 76920.416 | ... DR37: =SUMPRODUCT((Assumptions!$C$4:$C$9<=DR2)*'Acq & Financing'!$E$4:$E$9*Assumptions!$E$4:$E$9)/12 -> 497337.29
A38: NET CASH FLOW (levered, pre-tax) | C38: =C36-C37 -> -155109.03 | D38: =D36-D37 -> -150326.3 | E38: =E36-E37 -> -145543.56 | F38: =F36-F37 -> -140760.82 | G38: =G36-G37 -> -135978.09 | H38: =H36-H37 -> -131195.35 | I38: =I36-I37 -> -126412.62 | J38: =J36-J37 -> -121629.88 | ... DR38: =DR36-DR37 -> 587845.53
A39: EQUITY CASH FLOW & RETURNS
A40: Equity invested | C40: =-SUMPRODUCT((Assumptions!$C$4:$C$9=C2)*'Acq & Financing'!$F$4:$F$9) -> -7363321.9 | D40: =-SUMPRODUCT((Assumptions!$C$4:$C$9=D2)*'Acq & Financing'!$F$4:$F$9) -> 0 | E40: =-SUMPRODUCT((Assumptions!$C$4:$C$9=E2)*'Acq & Financing'!$F$4:$F$9) -> 0 | F40: =-SUMPRODUCT((Assumptions!$C$4:$C$9=F2)*'Acq & Financing'!$F$4:$F$9) -> 0 | G40: =-SUMPRODUCT((Assumptions!$C$4:$C$9=G2)*'Acq & Financing'!$F$4:$F$9) -> 0 | H40: =-SUMPRODUCT((Assumptions!$C$4:$C$9=H2)*'Acq & Financing'!$F$4:$F$9) -> 0 | I40: =-SUMPRODUCT((Assumptions!$C$4:$C$9=I2)*'Acq & Financing'!$F$4:$F$9) -> 0 | J40: =-SUMPRODUCT((Assumptions!$C$4:$C$9=J2)*'Acq & Financing'!$F$4:$F$9) -> 0 | ... DR40: =-SUMPRODUCT((Assumptions!$C$4:$C$9=DR2)*'Acq & Financing'!$F$4:$F$9) -> 0
A41: Date | C41: =DATE(2026,7,1) -> 46204 | D41: =EDATE(C41,1) -> 46235 | E41: =EDATE(D41,1) -> 46266 | F41: =EDATE(E41,1) -> 46296 | G41: =EDATE(F41,1) -> 46327 | H41: =EDATE(G41,1) -> 46357 | I41: =EDATE(H41,1) -> 46388 | J41: =EDATE(I41,1) -> 46419 | K41: =EDATE(J41,1) -> 46447 | ... DR41: =EDATE(DQ41,1) -> 49827
A42: Operating cash flow | C42: =C38 -> -155109.03 | D42: =D38 -> -150326.3 | E42: =E38 -> -145543.56 | F42: =F38 -> -140760.82 | G42: =G38 -> -135978.09 | H42: =H38 -> -131195.35 | I42: =I38 -> -126412.62 | J42: =J38 -> -121629.88 | ... DR42: =DR38 -> 587845.53
A43: Exit proceeds | C43: =IF(C2=120,$B$55,0) -> 0 | D43: =IF(D2=120,$B$55,0) -> 0 | E43: =IF(E2=120,$B$55,0) -> 0 | F43: =IF(F2=120,$B$55,0) -> 0 | G43: =IF(G2=120,$B$55,0) -> 0 | H43: =IF(H2=120,$B$55,0) -> 0 | I43: =IF(I2=120,$B$55,0) -> 0 | J43: =IF(J2=120,$B$55,0) -> 0 | ... DR43: =IF(DR2=120,$B$55,0) -> 1.1089369e+08
...

Sheet Annual Summary
A1: Annual Summary (Years 1-10)
A2: Year | C2: 1 | D2: 2 | E2: 3 | F2: 4 | G2: 5 | H2: 6 | I2: 7 | J2: 8 | K2: 9 | L2: 10
A3: Revenue | C3: =SUMIFS('Operating Model'!$C$25:$DR$25,'Operating Model'!$C$3:$DR$3,C2) -> 287112.11 | D3: =SUMIFS('Operating Model'!$C$25:$DR$25,'Operating Model'!$C$3:$DR$3,D2) -> 841680.19 | E3: =SUMIFS('Operating Model'!$C$25:$DR$25,'Operating Model'!$C$3:$DR$3,E2) -> 1758142.4 | F3: =SUMIFS('Operating Model'!$C$25:$DR$25,'Operating Model'!$C$3:$DR$3,F2) -> 2938886.3 | G3: =SUMIFS('Operating Model'!$C$25:$DR$25,'Operating Model'!$C$3:$DR$3,G2) -> 4616161.2 | H3: =SUMIFS('Operating Model'!$C$25:$DR$25,'Operating Model'!$C$3:$DR$3,H2) -> 6942186.7 | I3: =SUMIFS('Operating Model'!$C$25:$DR$25,'Operating Model'!$C$3:$DR$3,I2) -> 9726218.4 | J3: =SUMIFS('Operating Model'!$C$25:$DR$25,'Operating Model'!$C$3:$DR$3,J2) -> 12331481 | ... L3: =SUMIFS('Operating Model'!$C$25:$DR$25,'Operating Model'!$C$3:$DR$3,L2) -> 14988731
A4: NOI | C4: =SUMIFS('Operating Model'!$C$29:$DR$29,'Operating Model'!$C$3:$DR$3,C2) -> -239446.57 | D4: =SUMIFS('Operating Model'!$C$29:$DR$29,'Operating Model'!$C$3:$DR$3,D2) -> 473046.97 | E4: =SUMIFS('Operating Model'!$C$29:$DR$29,'Operating Model'!$C$3:$DR$3,E2) -> 1018632.5 | F4: =SUMIFS('Operating Model'!$C$29:$DR$29,'Operating Model'!$C$3:$DR$3,F2) -> 1974571.3 | G4: =SUMIFS('Operating Model'!$C$29:$DR$29,'Operating Model'!$C$3:$DR$3,G2) -> 3185793.5 | H4: =SUMIFS('Operating Model'!$C$29:$DR$29,'Operating Model'!$C$3:$DR$3,H2) -> 5181124.2 | I4: =SUMIFS('Operating Model'!$C$29:$DR$29,'Operating Model'!$C$3:$DR$3,I2) -> 7709041.2 | J4: =SUMIFS('Operating Model'!$C$29:$DR$29,'Operating Model'!$C$3:$DR$3,J2) -> 10849192 | ... L4: =SUMIFS('Operating Model'!$C$29:$DR$29,'Operating Model'!$C$3:$DR$3,L2) -> 13904694
A5: Corporate G&A | C5: =SUMIFS('Operating Model'!$C$32:$DR$32,'Operating Model'!$C$3:$DR$3,C2) -> 300000 | D5: =SUMIFS('Operating Model'!$C$32:$DR$32,'Operating Model'!$C$3:$DR$3,D2) -> 300000 | E5: =SUMIFS('Operating Model'!$C$32:$DR$32,'Operating Model'!$C$3:$DR$3,E2) -> 375000 | F5: =SUMIFS('Operating Model'!$C$32:$DR$32,'Operating Model'!$C$3:$DR$3,F2) -> 450000 | G5: =SUMIFS('Operating Model'!$C$32:$DR$32,'Operating Model'!$C$3:$DR$3,G2) -> 525000 | H5: =SUMIFS('Operating Model'!$C$32:$DR$32,'Operating Model'!$C$3:$DR$3,H2) -> 600000 | I5: =SUMIFS('Operating Model'!$C$32:$DR$32,'Operating Model'!$C$3:$DR$3,I2) -> 675000 | J5: =SUMIFS('Operating Model'!$C$32:$DR$32,'Operating Model'!$C$3:$DR$3,J2) -> 675000 | ... L5: =SUMIFS('Operating Model'!$C$32:$DR$32,'Operating Model'!$C$3:$DR$3,L2) -> 675000
A6: Operating profit | C6: =SUMIFS('Operating Model'!$C$36:$DR$36,'Operating Model'!$C$3:$DR$3,C2) -> -622602.82 | D6: =SUMIFS('Operating Model'!$C$36:$DR$36,'Operating Model'!$C$3:$DR$3,D2) -> 89083.536 | E6: =SUMIFS('Operating Model'!$C$36:$DR$36,'Operating Model'!$C$3:$DR$3,E2) -> 494042.86 | F6: =SUMIFS('Operating Model'!$C$36:$DR$36,'Operating Model'!$C$3:$DR$3,F2) -> 1354969.1 | G6: =SUMIFS('Operating Model'!$C$36:$DR$36,'Operating Model'!$C$3:$DR$3,G2) -> 2398791.5 | H6: =SUMIFS('Operating Model'!$C$36:$DR$36,'Operating Model'!$C$3:$DR$3,H2) -> 4265269.2 | I6: =SUMIFS('Operating Model'!$C$36:$DR$36,'Operating Model'!$C$3:$DR$3,I2) -> 6658852 | J6: =SUMIFS('Operating Model'!$C$36:$DR$36,'Operating Model'!$C$3:$DR$3,J2) -> 9852145.9 | ... L6: =SUMIFS('Operating Model'!$C$36:$DR$36,'Operating Model'!$C$3:$DR$3,L2) -> 13022194
A7: Interest | C7: =SUMIFS('Operating Model'!$C$37:$DR$37,'Operating Model'!$C$3:$DR$3,C2) -> 923044.99 | D7: =SUMIFS('Operating Model'!$C$37:$DR$37,'Operating Model'!$C$3:$DR$3,D2) -> 923044.99 | E7: =SUMIFS('Operating Model'!$C$37:$DR$37,'Operating Model'!$C$3:$DR$3,E2) -> 1846090 | F7: =SUMIFS('Operating Model'!$C$37:$DR$37,'Operating Model'!$C$3:$DR$3,F2) -> 2549362.4 | G7: =SUMIFS('Operating Model'!$C$37:$DR$37,'Operating Model'!$C$3:$DR$3,G2) -> 3721483 | H7: =SUMIFS('Operating Model'!$C$37:$DR$37,'Operating Model'!$C$3:$DR$3,H2) -> 4844765.2 | I7: =SUMIFS('Operating Model'!$C$37:$DR$37,'Operating Model'!$C$3:$DR$3,I2) -> 5968047.5 | J7: =SUMIFS('Operating Model'!$C$37:$DR$37,'Operating Model'!$C$3:$DR$3,J2) -> 5968047.5 | ... L7: =SUMIFS('Operating Model'!$C$37:$DR$37,'Operating Model'!$C$3:$DR$3,L2) -> 5968047.5
A8: Net cash flow (levered) | C8: =SUMIFS('Operating Model'!$C$38:$DR$38,'Operating Model'!$C$3:$DR$3,C2) -> -1545647.8 | D8: =SUMIFS('Operating Model'!$C$38:$DR$38,'Operating Model'!$C$3:$DR$3,D2) -> -833961.46 | E8: =SUMIFS('Operating Model'!$C$38:$DR$38,'Operating Model'!$C$3:$DR$3,E2) -> -1352047.1 | F8: =SUMIFS('Operating Model'!$C$38:$DR$38,'Operating Model'!$C$3:$DR$3,F2) -> -1194393.3 | G8: =SUMIFS('Operating Model'!$C$38:$DR$38,'Operating Model'!$C$3:$DR$3,G2) -> -1322691.5 | H8: =SUMIFS('Operating Model'!$C$38:$DR$38,'Operating Model'!$C$3:$DR$3,H2) -> -579496.02 | I8: =SUMIFS('Operating Model'!$C$38:$DR$38,'Operating Model'!$C$3:$DR$3,I2) -> 690804.52 | J8: =SUMIFS('Operating Model'!$C$38:$DR$38,'Operating Model'!$C$3:$DR$3,J2) -> 3884098.4 | ... L8: =SUMIFS('Operating Model'!$C$38:$DR$38,'Operating Model'!$C$3:$DR$3,L2) -> 7054146.4
A9: Cumulative net cash flow | C9: =C8 -> -1545647.8 | D9: =C9+D8 -> -2379609.3 | E9: =D9+E8 -> -3731656.4 | F9: =E9+F8 -> -4926049.7 | G9: =F9+G8 -> -6248741.1 | H9: =G9+H8 -> -6828237.2 | I9: =H9+I8 -> -6137432.6 | J9: =I9+J8 -> -2253334.2 | K9: =J9+K8 -> 3777667.6 | L9: =K9+L8 -> 10831814
A10: Owned SF (year-end) | C10: =INDEX('Operating Model'!$C$6:$DR$6,1,C2*12) -> 175000 | D10: =INDEX('Operating Model'!$C$6:$DR$6,1,D2*12) -> 175000 | E10: =INDEX('Operating Model'!$C$6:$DR$6,1,E2*12) -> 350000 | F10: =INDEX('Operating Model'!$C$6:$DR$6,1,F2*12) -> 500000 | G10: =INDEX('Operating Model'!$C$6:$DR$6,1,G2*12) -> 750000 | H10: =INDEX('Operating Model'!$C$6:$DR$6,1,H2*12) -> 1000000 | I10: =INDEX('Operating Model'!$C$6:$DR$6,1,I2*12) -> 1250000 | J10: =INDEX('Operating Model'!$C$6:$DR$6,1,J2*12) -> 1250000 | ... L10: =INDEX('Operating Model'!$C$6:$DR$6,1,L2*12) -> 1250000
A11: Occupancy (year-end) | C11: =INDEX('Operating Model'!$C$16:$DR$16,1,C2*12) -> 0.3 | D11: =INDEX('Operating Model'!$C$16:$DR$16,1,D2*12) -> 0.6 | E11: =INDEX('Operating Model'!$C$16:$DR$16,1,E2*12) -> 0.6 | F11: =INDEX('Operating Model'!$C$16:$DR$16,1,F2*12) -> 0.615 | G11: =INDEX('Operating Model'!$C$16:$DR$16,1,G2*12) -> 0.64 | H11: =INDEX('Operating Model'!$C$16:$DR$16,1,H2*12) -> 0.675 | I11: =INDEX('Operating Model'!$C$16:$DR$16,1,I2*12) -> 0.72 | J11: =INDEX('Operating Model'!$C$16:$DR$16,1,J2*12) -> 0.84 | ... L11: =INDEX('Operating Model'!$C$16:$DR$16,1,L2*12) -> 0.9
A12: Approx. breakeven occupancy | C12: =IF(C10=0,0,(C5+C7)/(Assumptions!$B$23*C10)) -> 0.68183693 | D12: =IF(D10=0,0,(D5+D7)/(Assumptions!$B$23*D10)) -> 0.68183693 | E12: =IF(E10=0,0,(E5+E7)/(Assumptions!$B$23*E10)) -> 0.61911916 | F12: =IF(F10=0,0,(F5+F7)/(Assumptions!$B$23*F10)) -> 0.58524144 | G12: =IF(G10=0,0,(G5+G7)/(Assumptions!$B$23*G10)) -> 0.55238803 | H12: =IF(H10=0,0,(H5+H7)/(Assumptions!$B$23*H10)) -> 0.53119661 | I12: =IF(I10=0,0,(I5+I7)/(Assumptions!$B$23*I10)) -> 0.51848176 | J12: =IF(J10=0,0,(J5+J7)/(Assumptions!$B$23*J10)) -> 0.51848176 | ... L12: =IF(L10=0,0,(L5+L7)/(Assumptions!$B$23*L10)) -> 0.51848176

Sheet Sensitivity Analysis
A1: Sensitivity Analysis - Portfolio Levered IRR
A2: Base-case IRR = 12.7%. Each cell recomputes the portfolio levered IRR from the full model, holding all other assumptions at the base case. Values are computed snapshots; re-run if base assumptions change.
A5: Table A — Acquisition price ($/SF) vs. Blended rent ($/SF, NNN)
B6: Acq $/SF \ Rent $/SF | C6: 9.75 | D6: 10.25 | E6: 10.75 | F6: 11.25
B7: 85 | C7: 0.13876463 | D7: 0.15798544 | E7: 0.17583624 | F7: 0.1925255
B8: 95 | C8: 0.10719536 | D8: 0.12740644 | E8: 0.14605174 | F8: 0.16338474
B9: 105 | C9: 0.076145957 | D9: 0.097568133 | E9: 0.11718089 | F9: 0.13529736
B10: 115 | C10: 0.045169384 | D10: 0.06807049 | E10: 0.088853528 | F10: 0.10791233
A14: Table B — Exit cap rate vs. Annual rent growth
B15: Exit cap \ Rent growth | C15: 0.02 | D15: 0.03 | E15: 0.04 | F15: 0.05
B16: 0.055 | C16: 0.14089252 | D16: 0.17032305 | E16: 0.19792411 | F16: 0.22403194
B17: 0.06 | C17: 0.11738268 | D17: 0.14841789 | E17: 0.17729194 | F17: 0.20443048
B18: 0.065 | C18: 0.094590149 | D18: 0.12740644 | E18: 0.15766762 | F18: 0.18591317
B19: 0.07 | C19: 0.072251823 | D19: 0.10705844 | E19: 0.13883781 | F19: 0.16827569
B20: 0.075 | C20: 0.050128291 | D20: 0.087176673 | E20: 0.12062621 | F20: 0.15135265
